Workbook

Sheet Vertical
B1: Compañía Cartrans Lmitada
B2: Balances Generales (miles de $) | G2: Análisis Vertical
C3: 2007 | D3: 2008 | E3: 2009 | G3: 2007 | H3: 2008 | I3: 2009
B4: Activos
B5: Caja | C5: 5148.31 | D5: 4002.48 | E5: 3905.77 | G5: =C5/$C$14 -> 0.092025623 | H5: =D5/$D$14 -> 0.056420661 | I5: =E5/$E$14 -> 0.040642345
B6: Cuentas por Cobrar | C6: 17097.75 | D6: 18462 | E6: 29356.86 | G6: =C6/$C$14 -> 0.30562089 | H6: =D6/$D$14 -> 0.26024821 | I6: =E6/$E$14 -> 0.30547924
B7: Inventarios | C7: 18933.75 | D7: 33028.87 | E7: 46658.62 | G7: =C7/$C$14 -> 0.33843924 | H7: =D7/$D$14 -> 0.465589 | I7: =E7/$E$14 -> 0.48551649
B8: Activo Circulante | C8: =SUM(C5:C7) -> 41179.81 | D8: =SUM(D5:D7) -> 55493.35 | E8: =SUM(E5:E7) -> 79921.25 | G8: =C8/$C$14 -> 0.73608576 | H8: =D8/$D$14 -> 0.78225787 | I8: =E8/$E$14 -> 0.83163807
B10: Activo Fijo bruto | C10: 17760.75 | D10: 20100.37 | E10: 22873.5 | G10: =C10/$C$14 -> 0.31747196 | H10: =D10/$D$14 -> 0.28334337 | I10: =E10/$E$14 -> 0.23801521
B11: Depreciación Acumulada | C11: -2996.25 | D11: -4653.75 | E11: -6693.75 | G11: =C11/$C$14 -> -0.053557726 | H11: =D11/$D$14 -> -0.06560124 | I11: =E11/$E$14 -> -0.069653281
B12: Activo Fijo Neto | C12: =C10+C11 -> 14764.5 | D12: =D10+D11 -> 15446.62 | E12: =E10+E11 -> 16179.75 | G12: =G10+G11 -> 0.26391424 | H12: =H10+H11 -> 0.21774213 | I12: =I10+I11 -> 0.16836193
B14: Total Activos | C14: =C8+C10+C11 -> 55944.31 | D14: =D8+D10+D11 -> 70939.97 | E14: =E8+E10+E11 -> 96101 | G14: =SUM(G5:G11)-G8 -> 1 | H14: =SUM(H5:H11)-H8 -> 1 | I14: =SUM(I5:I11)-I8 -> 1
B16: Pasivo y Patrimonio
B17: Deuda Corto Plazo | C17: 3187.5 | D17: 5100 | E17: 18232.5 | G17: =C17/C33 -> 0.056976304 | H17: =D17/$D$33 -> 0.07189177 | I17: =E17/$E$33 -> 0.18972227
B18: Cuentas por Pagar | C18: 6763.88 | D18: 10506.01 | E18: 19998.39 | G18: =C18/$C$33 -> 0.12090381 | H18: =D18/$D$33 -> 0.14809719 | I18: =E18/$E$33 -> 0.20809763
B19: Otros | C19: 3442.5 | D19: 5100 | E19: 7331.28 | G19: =C19/$C$33 -> 0.061534408 | H19: =D19/$D$33 -> 0.07189177 | I19: =E19/$E$33 -> 0.076287239
B21: Pasivo Circulante | C21: =SUM(C17:C20) -> 13393.88 | D21: =SUM(D17:D20) -> 20706.01 | E21: =SUM(E17:E20) -> 45562.17 | G21: =C21/$C$33 -> 0.23941452 | H21: =D21/$D$33 -> 0.29188073 | I21: =E21/$E$33 -> 0.47410714
B23: Deuda Largo Plazo | C23: 6375 | D23: 9562.5 | E23: 9562.5 | G23: =C23/$C$33 -> 0.11395261 | H23: =D23/$D$33 -> 0.13479707 | I23: =E23/$E$33 -> 0.099504688
B24: Deuda Largo Plazo - Hipoteca | C24: 2868.75 | D24: 2601 | E24: 2339.62 | G24: =C24/$C$33 -> 0.051278673 | H24: =D24/$D$33 -> 0.036664803 | I24: =E24/$E$33 -> 0.024345428
B26: Pasivo Largo Plazo | C26: =C23+C24 -> 9243.75 | D26: =D23+D24 -> 12163.5 | E26: =E23+E24 -> 11902.12 | G26: =C26/$C$33 -> 0.16523128 | H26: =D26/$D$33 -> 0.17146187 | I26: =E26/$E$33 -> 0.12385012
B28: Capital | C28: 23269 | D28: 23269 | E28: 23269 | G28: =C28/$C$33 -> 0.41593149 | H28: =D28/$D$33 -> 0.32800972 | I28: =E28/$E$33 -> 0.24213068
B29: Utilidades Retenidas | C29: 10037.68 | D29: 14801.46 | E29: 15367.71 | G29: =C29/$C$33 -> 0.17942272 | H29: =D29/$D$33 -> 0.20864768 | I29: =E29/$E$33 -> 0.15991207
B31: Patrimonio | C31: =C28+C29 -> 33306.68 | D31: =D28+D29 -> 38070.46 | E31: =E28+E29 -> 38636.71 | G31: =C31/$C$33 -> 0.5953542 | H31: =D31/$D$33 -> 0.5366574 | I31: =E31/$E$33 -> 0.40204275
B33: Pasivo y Patrimonio | C33: =C31+C26+C21 -> 55944.31 | D33: =D31+D26+D21 -> 70939.97 | E33: =E31+E26+E21 -> 96101 | G33: =C33/$C$33 -> 1 | H33: =D33/$D$33 -> 1 | I33: =E33/$E$33 -> 1
B36: Estado de Resultados (miles de S)
C37: 2007 | D37: 2008 | E37: 2009 | G37: 2007 | H37: 2008 | I37: 2009
B39: Ventas Netas | C39: 170997.5 | D39: 184658.25 | E39: 195731.63 | G39: 1 | H39: 1 | I39: 1
B40: Costo de Ventas | C40: -135267.74 | D40: -150131.22 | E40: -166642.58 | G40: =-C40/$C$39 -> 0.79105098 | H40: =-D40/D39 -> 0.813022 | I40: =-E40/E39 -> 0.85138299
B42: Margen Bruto | C42: =C39+C40 -> 35729.76 | D42: =D39+D40 -> 34527.03 | E42: =E39+E40 -> 29089.05 | G42: =G39-G40 -> 0.20894902 | H42: =H39-H40 -> 0.186978 | I42: =I39-I40 -> 0.14861701
B44: Gastos de Adm. y Ventas | C44: -12789.79 | D44: -15344.64 | E44: -16880.96 | G44: =-C44/$C$39 -> 0.074795187 | H44: =-D44/$D$39 -> 0.083097506 | I44: =-E44/$E$39 -> 0.086245437
B45: Gasto por Depreciación | C45: -1593.75 | D45: -1657.5 | E45: -2040 | G45: =-C45/$C$39 -> 0.0093203117 | H45: =-D45/$D$39 -> 0.0089760409 | I45: =-E45/$E$39 -> 0.010422434
B46: Gastos Varios | C46: -2027.49 | D46: -3557.25 | E46: -5724.72 | G46: =-C46/$C$39 -> 0.01185684 | H46: =-D46/$D$39 -> 0.019263965 | I46: =-E46/$E$39 -> 0.029247802
B48: Resultado Operacional | C48: =C42+C44+C45+C46 -> 19318.73 | D48: =D42+D44+D45+D46 -> 13967.64 | E48: =E42+E44+E45+E46 -> 4443.37 | G48: =C48/$C$39 -> 0.11297668 | H48: =D48/$D$39 -> 0.075640487 | I48: =E48/$E$39 -> 0.022701339
B50: Gasto por Intereses | C50: =-318.75-637.5-259.83 -> -1216.08 | D50: =-561-956.25-235.58 -> -1752.83 | E50: =-1823.25-956.25-211.9 -> -2991.4 | G50: =-C50/$C$39 -> 0.0071116829 | H50: =-D50/$D$39 -> 0.0094922918 | I50: =-E50/$E$39 -> 0.015283171
B52: UA.I. | C52: =C48+C50 -> 18102.65 | D52: =D48+D50 -> 12214.81 | E52: =E48+E50 -> 1451.97 | G52: =C52/$C$39 -> 0.105865 | H52: =D52/$D$39 -> 0.066148195 | I52: =E52/$E$39 -> 0.0074181674
B54: Impuestos | C54: -8689.26 | D54: -5863.1 | E54: -696.94 | G54: =-C54/$C$39 -> 0.050815129 | H54: =-D54/$D$39 -> 0.031751086 | I54: =-E54/$E$39 -> 0.0035606917
B56: Utilidad Neta | C56: =C52+C54 -> 9413.39 | D56: =D52+D54 -> 6351.71 | E56: =E52+E54 -> 755.03 | G56: =C56/$C$39 -> 0.055049869 | H56: =D56/$D$39 -> 0.034397109 | I56: =E56/$E$39 -> 0.0038574757

Sheet Horizontal
B1: Compañía Cartrans Lmitada
B2: Balances Generales (miles de $) | G2: Análisis Horizontal
C3: 2007 | D3: 2008 | E3: 2009 | G3: 2007 | H3: 2008 | I3: 2009
B4: Activos
B5: Caja | C5: 5148.31 | D5: 4002.48 | E5: 3905.77 | G5: 1 | H5: =D5/C5 -> 0.7774357 | I5: =E5/C5 -> 0.7586509
B6: Cuentas por Cobrar | C6: 17097.75 | D6: 18462 | E6: 29356.86 | G6: 1 | H6: =D6/C6 -> 1.0797912 | I6: =E6/C6 -> 1.7170014
B7: Inventarios | C7: 18933.75 | D7: 33028.87 | E7: 46658.62 | G7: 1 | H7: =D7/C7 -> 1.7444442 | I7: =E7/C7 -> 2.4643095
B8: Activo Circulante | C8: =SUM(C5:C7) -> 41179.81 | D8: =SUM(D5:D7) -> 55493.35 | E8: =SUM(E5:E7) -> 79921.25 | G8: 1 | H8: =D8/C8 -> 1.3475864 | I8: =E8/C8 -> 1.9407872
B10: Activo Fijo bruto | C10: 17760.75 | D10: 20100.37 | E10: 22873.5 | G10: 1 | H10: =D10/C10 -> 1.1317298 | I10: =E10/C10 -> 1.2878679
B11: Depreciación Acumulada | C11: -2996.25 | D11: -4653.75 | E11: -6693.75 | G11: 1 | H11: =D11/C11 -> 1.5531915 | I11: =E11/C11 -> 2.2340426
B12: Activo Fijo Neto | C12: =C10+C11 -> 14764.5 | D12: =D10+D11 -> 15446.62 | E12: =E10+E11 -> 16179.75 | G12: 1 | H12: =D12/C12 -> 1.0462 | I12: =E12/C12 -> 1.0958549
B14: Total Activos | C14: =C8+C10+C11 -> 55944.31 | D14: =D8+D10+D11 -> 70939.97 | E14: =E8+E10+E11 -> 96101 | G14: 1 | H14: =D14/C14 -> 1.2680462 | I14: =E14/C14 -> 1.7177976
B16: Pasivo y Patrimonio
B17: Deuda Corto Plazo | C17: 3187.5 | D17: 5100 | E17: 18232.5 | G17: 1 | H17: =D17/C17 -> 1.6 | I17: =E17/C17 -> 5.72
B18: Cuentas por Pagar | C18: 6763.88 | D18: 10506.01 | E18: 19998.39 | G18: 1 | H18: =D18/C18 -> 1.553252 | I18: =E18/C18 -> 2.9566447
B19: Otros | C19: 3442.5 | D19: 5100 | E19: 7331.28 | G19: 1 | H19: =D19/C19 -> 1.4814815 | I19: =E19/C19 -> 2.1296383
B21: Pasivo Circulante | C21: =SUM(C17:C20) -> 13393.88 | D21: =SUM(D17:D20) -> 20706.01 | E21: =SUM(E17:E20) -> 45562.17 | G21: 1 | H21: =D21/C21 -> 1.5459307 | I21: =E21/C21 -> 3.4017156
B23: Deuda Largo Plazo | C23: 6375 | D23: 9562.5 | E23: 9562.5 | G23: 1 | H23: =D23/C23 -> 1.5 | I23: =E23/C23 -> 1.5
B24: Deuda Largo Plazo - Hipoteca | C24: 2868.75 | D24: 2601 | E24: 2339.62 | G24: 1 | H24: =D24/C24 -> 0.90666667 | I24: =E24/C24 -> 0.81555381
B26: Pasivo Largo Plazo | C26: =C23+C24 -> 9243.75 | D26: =D23+D24 -> 12163.5 | E26: =E23+E24 -> 11902.12 | G26: 1 | H26: =D26/C26 -> 1.3158621 | I26: =E26/C26 -> 1.2875857
B28: Capital | C28: 23269 | D28: 23269 | E28: 23269 | G28: 1 | H28: =D28/C28 -> 1 | I28: =E28/C28 -> 1
B29: Utilidades Retenidas | C29: 10037.68 | D29: 14801.46 | E29: 15367.71 | G29: 1 | H29: =D29/C29 -> 1.4745897 | I29: =E29/C29 -> 1.5310022
B31: Patrimonio | C31: =C28+C29 -> 33306.68 | D31: =D28+D29 -> 38070.46 | E31: =E28+E29 -> 38636.71 | G31: 1 | H31: =D31/C31 -> 1.1430278 | I31: =E31/C31 -> 1.1600289
B33: Pasivo y Patrimonio | C33: =C31+C26+C21 -> 55944.31 | D33: =D31+D26+D21 -> 70939.97 | E33: =E31+E26+E21 -> 96101 | G33: =C33/$C$33 -> 1 | H33: =D33/C33 -> 1.2680462 | I33: =E33/C33 -> 1.7177976
B36: Estado de Resultados (miles de S)
C37: 2007 | D37: 2008 | E37: 2009 | G37: 2007 | H37: 2008 | I37: 2009
B39: Ventas Netas | C39: 170997.5 | D39: 184658.25 | E39: 195731.63 | G39: 1 | H39: =D39/C39 -> 1.0798886 | I39: =E39/C39 -> 1.1446461
B40: Costo de Ventas | C40: -135267.74 | D40: -150131.22 | E40: -166642.58 | G40: 1 | H40: =D40/C40 -> 1.1098819 | I40: =E40/C40 -> 1.2319462
B42: Margen Bruto | C42: =C39+C40 -> 35729.76 | D42: =D39+D40 -> 34527.03 | E42: =E39+E40 -> 29089.05 | G42: 1 | H42: =D42/C42 -> 0.96633815 | I42: =E42/C42 -> 0.81414065
B44: Gastos de Adm. y Ventas | C44: -12789.79 | D44: -15344.64 | E44: -16880.96 | G44: 1 | H44: =D44/C44 -> 1.199757 | I44: =E44/C44 -> 1.3198778
B45: Gasto por Depreciación | C45: -1593.75 | D45: -1657.5 | E45: -2040 | G45: 1 | H45: =D45/C45 -> 1.04 | I45: =E45/C45 -> 1.28
B46: Gastos Varios | C46: -2027.49 | D46: -3557.25 | E46: -5724.72 | G46: 1 | H46: =D46/C46 -> 1.7545093 | I46: =E46/C46 -> 2.8235503
B48: Resultado Operacional | C48: =C42+C44+C45+C46 -> 19318.73 | D48: =D42+D44+D45+D46 -> 13967.64 | E48: =E42+E44+E45+E46 -> 4443.37 | G48: 1 | H48: =D48/C48 -> 0.72301026 | I48: =E48/C48 -> 0.23000321
B50: Gasto por Intereses | C50: =-318.75-637.5-259.83 -> -1216.08 | D50: =-561-956.25-235.58 -> -1752.83 | E50: =-1823.25-956.25-211.9 -> -2991.4 | G50: 1 | H50: =D50/C50 -> 1.4413772 | I50: =E50/C50 -> 2.4598711
B52: UA.I. | C52: =C48+C50 -> 18102.65 | D52: =D48+D50 -> 12214.81 | E52: =E48+E50 -> 1451.97 | G52: 1 | H52: =D52/C52 -> 0.67475259 | I52: =E52/C52 -> 0.080207594
B54: Impuestos | C54: -8689.26 | D54: -5863.1 | E54: -696.94 | G54: 1 | H54: =D54/C54 -> 0.67475251 | I54: =E54/C54 -> 0.08020706
B56: Utilidad Neta | C56: =C52+C54 -> 9413.39 | D56: =D52+D54 -> 6351.71 | E56: =E52+E54 -> 755.03 | G56: 1 | H56: =D56/C56 -> 0.67475267 | I56: =E56/C56 -> 0.080208087

Sheet Ratios
B1: Relaciones Financieras
B2: Medidas de Rendimiento Financiero
B4: Retorno sobre Activos (ROA)
B6: Rentabilidad | D6: 2007 | F6: 2008 | H6: 2009
B8: Utilidad Antes de Impuesto / Activo Total | C8: Retorno Sobre Activos (1) | D8: 18102.65 | E8: =D8/D9 -> 0.3235834 | F8: 12214.81 | G8: =F8/F9 -> 0.17218516 | H8: 1451.97 | I8: =H8/H9 -> 0.015108792
D9: 55944.31 | F9: 70939.97 | H9: 96101
B12: Utilidad despues de Impuesto /Activo Total | C12: Retorno Sobre Activos (2) | D12: 9413.39 | E12: =D12/D13 -> 0.16826358 | F12: 6351.71 | G12: =F12/F13 -> 0.089536407 | H12: 755.03 | I12: =H12/H13 -> 0.00785663
D13: =D9 -> 55944.31 | F13: =F9 -> 70939.97 | H13: =H9 -> 96101
B16: Retorno sobre Patrimonio (ROE)
B18: Utilidad Antes de Impuesto / Patrimonio | C18: Retorno Sobre Patrimonio (1) | D18: 18102.65 | E18: =D18/D19 -> 0.54351409 | F18: 12214.81 | G18: =F18/F19 -> 0.32084745 | H18: 1451.97 | I18: =H18/H19 -> 0.037580063
D19: 33306.68 | F19: 38070.46 | H19: 38636.71
B22: Utilidad despues de Impuesto /Patrimonio | C22: Retorno Sobre Patrimonio (2) | D22: 9413.39 | E22: =D22/D23 -> 0.28262769 | F22: 6351.71 | G22: =F22/F23 -> 0.1668409 | H22: 755.03 | I22: =H22/H23 -> 0.019541778
D23: =D19 -> 33306.68 | F23: =F19 -> 38070.46 | H23: =H19 -> 38636.71
B26: Eficiencia
B28: Utilidad Bruta / Ventas Netas | C28: Margen Bruto | D28: 35729.76 | E28: =D28/D29 -> 0.20894902 | F28: 34527.03 | G28: =F28/F29 -> 0.186978 | H28: 29089.05 | I28: =H28/H29 -> 0.14861701
D29: 170997.5 | F29: 184658.25 | H29: 195731.63
B31: Utilidad Operacional / Ventas Netas | C31: Margen Operacional | D31: 19318.73 | E31: =D31/D32 -> 0.11297668 | F31: 13967.64 | G31: =F31/F32 -> 0.075640487 | H31: 4443.37 | I31: =H31/H32 -> 0.022701339
D32: 170997.5 | F32: 184658.25 | H32: 195731.63
B34: Utilidad Antes de Impuesto / Ventas Netas | C34: Margen Neto (1) | D34: =D18 -> 18102.65 | E34: =D34/D35 -> 0.105865 | F34: =F18 -> 12214.81 | G34: =F34/F35 -> 0.066148195 | H34: =H18 -> 1451.97 | I34: =H34/H35 -> 0.0074181674
D35: 170997.5 | F35: 184658.25 | H35: 195731.63
B37: Utilidad después de Impuestos / Ventas Netas | C37: Margen Neto (2) | D37: =D22 -> 9413.39 | E37: =D37/D38 -> 0.055049869 | F37: =F22 -> 6351.71 | G37: =F37/F38 -> 0.034397109 | H37: =H22 -> 755.03 | I37: =H37/H38 -> 0.0038574757
D38: 170997.5 | F38: 184658.25 | H38: 195731.63
B40: Ventas Netas /Activo Total | C40: Rotación de Activos | D40: =D38 -> 170997.5 | E40: =D40/D41 -> 3.0565664 | F40: =F38 -> 184658.25 | G40: =F40/F41 -> 2.6030213 | H40: =H38 -> 195731.63 | I40: =H40/H41 -> 2.0367283
D41: =D9 -> 55944.31 | F41: =F9 -> 70939.97 | H41: =H9 -> 96101
B43: Ventas Netas / Inventarios (promedio o final) | C43: Rotación Inventarios (1) | D43: =D40 -> 170997.5 | E43: =D43/D44 -> 9.0313593 | F43: =F40 -> 184658.25 | G43: =F43/F44 -> 5.5908134 | H43: =H40 -> 195731.63 | I43: =H43/H44 -> 4.1949725
D44: 18933.75 | F44: 33028.87 | H44: 46658.62
B46: Costo de Ventas / Inventario (promedio o final) | C46: Rotación Inventarios (2) | D46: 135267.74 | E46: =D46/D47 -> 7.1442657 | F46: 150131.22 | G46: =F46/F47 -> 4.5454543 | H46: 166642.58 | I46: =H46/H47 -> 3.5715283
D47: =D44 -> 18933.75 | F47: =F44 -> 33028.87 | H47: =H44 -> 46658.62
B49: Ventas Netas / Cuentas por Cobrar (promedio o final) | C49: Rotación Cuentas por Cobrar | D49: =D43 -> 170997.5 | E49: =D49/D50 -> 10.00117 | F49: =F43 -> 184658.25 | G49: =F49/F50 -> 10.002072 | H49: =H43 -> 195731.63 | I49: =H49/H50 -> 6.6673217
D50: 17097.75 | F50: 18462 | H50: 29356.86
B52: Cuentas por Cobrar /Venta Diaria | C52: Periodo de Recuperación (dias) | D52: =D50 -> 17097.75 | E52: =D52/D53 -> 35.995789 | F52: =F50 -> 18462 | G52: =F52/F53 -> 35.992543 | H52: =H50 -> 29356.86 | I52: =H52/H53 -> 53.994695
D53: =D49/360 -> 474.99306 | F53: =F49/360 -> 512.93958 | H53: =H49/360 -> 543.69897
B55: Ventas Netas /Activo Fijo Bruto | C55: Rotación Activo Fijo (1) | D55: =D49 -> 170997.5 | E55: =D55/D56 -> 9.627831 | F55: =F49 -> 184658.25 | G55: =F55/F56 -> 9.1868085 | H55: =H49 -> 195731.63 | I55: =H55/H56 -> 8.5571351
D56: 17760.75 | F56: 20100.37 | H56: 22873.5
B58: Ventas Netas / Activo Fijo Neto | C58: Rotación Activo Fijo (2) | D58: =D55 -> 170997.5 | E58: =D58/D59 -> 11.581665 | F58: =F55 -> 184658.25 | G58: =F58/F59 -> 11.954606 | H58: =H55 -> 195731.63 | I58: =H58/H59 -> 12.097321
D59: 14764.5 | F59: 15446.62 | H59: 16179.75
B61: Inventarios / Costo de Venta dia | C61: Permanencia de Inventarios | D61: 18933.75 | E61: =D61/D62 -> 51.089925 | F61: 33028.87 | G61: =F61/F62 -> 80.299694 | H61: 46658.62 | I61: =H61/H62 -> 102.19603
D62: =-Vertical!C40/365 -> 370.59655 | F62: 411.32 | H62: 456.56
B64: Endeudamiento
B66: Deuda Total /Patrimonio | C66: Deuda Total a Capital | D66: 22637.63 | E66: =D66/D67 -> 0.67967237 | F66: 32869.51 | G66: =F66/F67 -> 0.86338621 | H66: 57464.29 | I66: =H66/H67 -> 1.4872977
...

Sheet Comparativo
A1: Comparación con promedios de la Industria
B3: Promedio Industria | C3: 2007 | D3: 2008 | E3: 2009 | F3: Promedio Empresa
A4: Razón Circulante | B4: 2.5 | C4: =Ratios!E80 -> 3.0745243 | D4: =Ratios!G80 -> 2.68006 | E4: =Ratios!I80 -> 1.7541142 | F4: =(C4+D4+E4)/3 -> 2.5028995
A6: Prueba Acida | B6: 1 | C6: =Ratios!E83 -> 1.6609123 | D6: =Ratios!G83 -> 1.0849256 | E6: =Ratios!I83 -> 0.73004929 | F6: =(C6+D6+E6)/3 -> 1.1586291
A8: Relación de endeudamiento | B8: 0.5 | C8: =Ratios!E66 -> 0.67967237 | D8: =Ratios!G66 -> 0.86338621 | E8: =Ratios!I66 -> 1.4872977 | F8: =(C8+D8+E8)/3 -> 1.0101188
A10: Rotación de Inventarios | B10: 7.7 | C10: =Ratios!E43 -> 9.0313593 | D10: =Ratios!G43 -> 5.5908134 | E10: =Ratios!I43 -> 4.1949725 | F10: =(C10+D10+E10)/3 -> 6.2723818
A12: Periodo Promedio de Cobranza | B12: 32 | C12: =Ratios!E52 -> 35.995789 | D12: =Ratios!G52 -> 35.992543 | E12: =Ratios!I52 -> 53.994695 | F12: =(C12+D12+E12)/3 -> 41.994342
A14: Margen Neto | B14: 0.029 | C14: =Ratios!E34 -> 0.105865 | D14: =Ratios!G34 -> 0.066148195 | E14: =Ratios!I34 -> 0.0074181674 | F14: =(C14+D14+E14)/3 -> 0.059810454
A16: ROA | B16: 0.088 | C16: =Ratios!E12 -> 0.16826358 | D16: =Ratios!G12 -> 0.089536407 | E16: =Ratios!I12 -> 0.00785663 | F16: =(C16+D16+E16)/3 -> 0.088552206
A18: ROE | B18: 0.175 | C18: =Ratios!E22 -> 0.28262769 | D18: =Ratios!G22 -> 0.1668409 | E18: =Ratios!I22 -> 0.019541778 | F18: =(C18+D18+E18)/3 -> 0.15633679

Sheet Du Pont
B1: Aplicación del Modelo Du Pont
B3: Retorno Sobre Patrimonio = Margen * Rotación * Endeudamiento
C5: Ut Neta | D5: = | E5: Ut Neta | F5: * | G5: Ventas | H5: * | I5: Activo Total
C6: Patrimonio | E6: Ventas | G6: Activo Total | I6: Patrimonio
B8: Promedio Industria | C8: =E8*G8*I8 -> 0.1305 | D8: = | E8: 0.029 | F8: * | G8: 3 | H8: * | I8: 1.5
B10: Cartrans
B12: 2007 | C12: =E12*G12*I12 -> 0.28262769 | D12: = | E12: =Ratios!E37 -> 0.055049869 | G12: =Ratios!E40 -> 3.0565664 | I12: =Ratios!E75 -> 1.6796724
B14: 2008 | C14: =E14*G14*I14 -> 0.1668409 | D14: = | E14: =Ratios!G37 -> 0.034397109 | G14: =Ratios!G40 -> 2.6030213 | I14: =Ratios!G75 -> 1.8633862
B16: 2009 | C16: =E16*G16*I16 -> 0.019541778 | D16: = | E16: =Ratios!I37 -> 0.0038574757 | G16: =Ratios!I40 -> 2.0367283 | I16: =Ratios!I75 -> 2.4872977
B18: Promedio Cartrans | C18: =AVERAGE(C12:C16) -> 0.15633679 | D18: = | E18: =AVERAGE(E12:E16) -> 0.031101485 | G18: =AVERAGE(G12:G16) -> 2.5654387 | I18: =AVERAGE(I12:I16) -> 2.0101188
