Workbook

Sheet EE.RR
A1: Consolidated Statement of Income
A2: 3M Company and Subsidiaries
A4: Years ended December 31 | B4: 2010 | C4: 2009 | D4: 2008
A5: (Millions US$)
A7: Net sales | B7: 26662 | C7: 23123 | D7: 25269
A8: Operating expenses
A9: Cost of sales | B9: 13831 | C9: 12109 | D9: 13379
A10: Gross Margin | B10: =B7-B9 -> 12831 | C10: =C7-C9 -> 11014 | D10: =D7-D9 -> 11890
A12: Selling, general and administrative expenses | B12: 5479 | C12: 4907 | D12: 5245
A13: Research, development and related expenses | B13: 1434 | C13: 1293 | D13: 1404
A14: Loss from sale of businesses | D14: 23
A15: Total operating expenses | B15: =SUM(B12:B14) -> 6913 | C15: =SUM(C12:C14) -> 6200 | D15: =SUM(D12:D14) -> 6672
A16: Operating income | B16: =B10-B15 -> 5918 | C16: =C10-C15 -> 4814 | D16: =D10-D15 -> 5218
A18: Interest expense and income
A19: Interest expense | B19: 201 | C19: 219 | D19: 215
A20: Interest income | B20: -38 | C20: -37 | D20: -105
A21: Total interest expense (income) | B21: =SUM(B19:B20) -> 163 | C21: =SUM(C19:C20) -> 182 | D21: =SUM(D19:D20) -> 110
A22: Income before income taxes | B22: =B16-B21 -> 5755 | C22: =C16-C21 -> 4632 | D22: =D16-D21 -> 5108
A23: Provision for income taxes | B23: 1592 | C23: 1388 | D23: 1588
A24: Net income including noncontrolling interest | B24: =B22-B23 -> 4163 | C24: =C22-C23 -> 3244 | D24: =D22-D23 -> 3520
A25: Less: Net income attributable to noncontrolling interest | B25: 78 | C25: 51 | D25: 60
A26: Net income attributable to 3M | B26: =B24-B25 -> 4085 | C26: =C24-C25 -> 3193 | D26: =D24-D25 -> 3460

Sheet EE.RR Vertical
A1: Consolidated Statement of Income
A2: 3M Company and Subsidiaries
F3: Análisis Vertical
A4: Years ended December 31 | B4: 2010 | C4: 2009 | D4: 2008 | F4: 2010 | G4: 2009 | H4: 2008
A5: (Millions US$)
A7: Net sales | B7: 26662 | C7: 23123 | D7: 25269 | F7: =B7/$B$7 -> 1 | G7: =C7/$C$7 -> 1 | H7: =D7/$D$7 -> 1
A8: Operating expenses
A9: Cost of sales | B9: 13831 | C9: 12109 | D9: 13379 | F9: =B9/$B$7 -> 0.51875328 | G9: =C9/$C$7 -> 0.52367772 | H9: =D9/$D$7 -> 0.52946298
A10: Gross Margin | B10: =B7-B9 -> 12831 | C10: =C7-C9 -> 11014 | D10: =D7-D9 -> 11890 | F10: =B10/$B$7 -> 0.48124672 | G10: =C10/$C$7 -> 0.47632228 | H10: =D10/$D$7 -> 0.47053702
A12: Selling, general and administrative expenses | B12: 5479 | C12: 4907 | D12: 5245 | F12: =B12/$B$7 -> 0.20549846 | G12: =C12/$C$7 -> 0.21221295 | H12: =D12/$D$7 -> 0.20756658
A13: Research, development and related expenses | B13: 1434 | C13: 1293 | D13: 1404 | F13: =B13/$B$7 -> 0.053784412 | G13: =C13/$C$7 -> 0.05591835 | H13: =D13/$D$7 -> 0.055562151
A14: Loss from sale of businesses | D14: 23 | H14: =D14/$D$7 -> 0.00091020618
A15: Total operating expenses | B15: =SUM(B12:B14) -> 6913 | C15: =SUM(C12:C14) -> 6200 | D15: =SUM(D12:D14) -> 6672 | F15: =B15/$B$7 -> 0.25928287 | G15: =C15/$C$7 -> 0.2681313 | H15: =D15/$D$7 -> 0.26403894
A16: Operating income | B16: =B10-B15 -> 5918 | C16: =C10-C15 -> 4814 | D16: =D10-D15 -> 5218 | F16: =B16/$B$7 -> 0.22196384 | G16: =C16/$C$7 -> 0.20819098 | H16: =D16/$D$7 -> 0.20649808
A18: Interest expense and income
A19: Interest expense | B19: 201 | C19: 219 | D19: 215 | F19: =B19/$B$7 -> 0.0075388193 | G19: =C19/$C$7 -> 0.0094710894 | H19: =D19/$D$7 -> 0.0085084491
A20: Interest income | B20: -38 | C20: -37 | D20: -105 | F20: =B20/$B$7 -> -0.0014252494 | G20: =C20/$C$7 -> -0.0016001384 | H20: =D20/$D$7 -> -0.0041552891
A21: Total interest expense (income) | B21: =SUM(B19:B20) -> 163 | C21: =SUM(C19:C20) -> 182 | D21: =SUM(D19:D20) -> 110 | F21: =B21/$B$7 -> 0.0061135699 | G21: =C21/$C$7 -> 0.007870951 | H21: =D21/$D$7 -> 0.00435316
A22: Income before income taxes | B22: =B16-B21 -> 5755 | C22: =C16-C21 -> 4632 | D22: =D16-D21 -> 5108 | F22: =B22/$B$7 -> 0.21585027 | G22: =C22/$C$7 -> 0.20032003 | H22: =D22/$D$7 -> 0.20214492
A23: Provision for income taxes | B23: 1592 | C23: 1388 | D23: 1588 | F23: =B23/$B$7 -> 0.059710449 | G23: =C23/$C$7 -> 0.060026813 | H23: =D23/$D$7 -> 0.062843801
A24: Net income including noncontrolling interest | B24: =B22-B23 -> 4163 | C24: =C22-C23 -> 3244 | D24: =D22-D23 -> 3520 | F24: =B24/$B$7 -> 0.15613982 | G24: =C24/$C$7 -> 0.14029321 | H24: =D24/$D$7 -> 0.13930112
A25: Less: Net income attributable to noncontrolling interest | B25: 78 | C25: 51 | D25: 60 | F25: =B25/$B$7 -> 0.002925512 | G25: =C25/$C$7 -> 0.0022055962 | H25: =D25/$D$7 -> 0.0023744509
A26: Net income attributable to 3M | B26: =B24-B25 -> 4085 | C26: =C24-C25 -> 3193 | D26: =D24-D25 -> 3460 | F26: =B26/$B$7 -> 0.15321431 | G26: =C26/$C$7 -> 0.13808762 | H26: =D26/$D$7 -> 0.13692667

Sheet EE.RR Horizontal
A1: Consolidated Statement of Income
A2: 3M Company and Subsidiaries
F3: Análisis Horizontal
A4: Years ended December 31 | B4: 2010 | C4: 2009 | D4: 2008 | F4: 2010 | G4: 2009 | H4: 2008
A5: (Millions US$)
A7: Net sales | B7: 26662 | C7: 23123 | D7: 25269 | F7: =B7/D7 -> 1.0551268 | G7: =(C7/D7) -> 0.91507381 | H7: =D7/D7 -> 1
A8: Operating expenses
A9: Cost of sales | B9: 13831 | C9: 12109 | D9: 13379 | F9: =B9/D9 -> 1.0337843 | G9: =(C9/D9) -> 0.90507512 | H9: =D9/D9 -> 1
A10: Gross Margin | B10: =B7-B9 -> 12831 | C10: =C7-C9 -> 11014 | D10: =D7-D9 -> 11890 | F10: =B10/D10 -> 1.0791421 | G10: =(C10/D10) -> 0.92632464 | H10: =D10/D10 -> 1
A12: Selling, general and administrative expenses | B12: 5479 | C12: 4907 | D12: 5245 | F12: =B12/D12 -> 1.0446139 | G12: =(C12/D12) -> 0.93555767 | H12: =D12/D12 -> 1
A13: Research, development and related expenses | B13: 1434 | C13: 1293 | D13: 1404 | F13: =B13/D13 -> 1.0213675 | G13: =(C13/D13) -> 0.92094017 | H13: =D13/D13 -> 1
A14: Loss from sale of businesses | D14: 23 | F14: =B14/D14 -> 0 | G14: =(C14/D14) -> 0 | H14: =D14/D14 -> 1
A15: Total operating expenses | B15: =SUM(B12:B14) -> 6913 | C15: =SUM(C12:C14) -> 6200 | D15: =SUM(D12:D14) -> 6672 | F15: =B15/D15 -> 1.0361211 | G15: =(C15/D15) -> 0.92925659 | H15: =D15/D15 -> 1
A16: Operating income | B16: =B10-B15 -> 5918 | C16: =C10-C15 -> 4814 | D16: =D10-D15 -> 5218 | F16: =B16/D16 -> 1.134151 | G16: =(C16/D16) -> 0.9225757 | H16: =D16/D16 -> 1
A18: Interest expense and income
A19: Interest expense | B19: 201 | C19: 219 | D19: 215 | F19: =B19/D19 -> 0.93488372 | G19: =(C19/D19) -> 1.0186047 | H19: =D19/D19 -> 1
A20: Interest income | B20: -38 | C20: -37 | D20: -105 | F20: =B20/D20 -> 0.36190476 | G20: =(C20/D20) -> 0.35238095 | H20: =D20/D20 -> 1
A21: Total interest expense (income) | B21: =SUM(B19:B20) -> 163 | C21: =SUM(C19:C20) -> 182 | D21: =SUM(D19:D20) -> 110 | F21: =B21/D21 -> 1.4818182 | G21: =(C21/D21) -> 1.6545455 | H21: =D21/D21 -> 1
A22: Income before income taxes | B22: =B16-B21 -> 5755 | C22: =C16-C21 -> 4632 | D22: =D16-D21 -> 5108 | F22: =B22/D22 -> 1.1266641 | G22: =(C22/D22) -> 0.90681284 | H22: =D22/D22 -> 1
A23: Provision for income taxes | B23: 1592 | C23: 1388 | D23: 1588 | F23: =B23/D23 -> 1.0025189 | G23: =(C23/D23) -> 0.87405542 | H23: =D23/D23 -> 1
A24: Net income including noncontrolling interest | B24: =B22-B23 -> 4163 | C24: =C22-C23 -> 3244 | D24: =D22-D23 -> 3520 | F24: =B24/D24 -> 1.1826705 | G24: =(C24/D24) -> 0.92159091 | H24: =D24/D24 -> 1
A25: Less: Net income attributable to noncontrolling interest | B25: 78 | C25: 51 | D25: 60 | F25: =B25/D25 -> 1.3 | G25: =(C25/D25) -> 0.85 | H25: =D25/D25 -> 1
A26: Net income attributable to 3M | B26: =B24-B25 -> 4085 | C26: =C24-C25 -> 3193 | D26: =D24-D25 -> 3460 | F26: =B26/D26 -> 1.1806358 | G26: =(C26/D26) -> 0.92283237 | H26: =D26/D26 -> 1

Sheet Balance
A1: Consolidated Statement of Income
A2: 3M Company and Subsidiaries
A3: At December 31
B5: Year | C5: Year
A6: (Dollars in millions) | B6: 2010 | C6: 2009
A7: Assets
A8: Current assets
A9: Cash and cash equivalents | B9: 3377 | C9: 3040
A10: Marketable securities — current | B10: 1101 | C10: 744
A11: Accounts receivable | B11: 3615 | C11: 3250
A13: Inventories
A14: Finished goods | B14: 1476 | C14: 1255
A15: Work in process | B15: 950 | C15: 815
A16: Raw materials and supplies | B16: 729 | C16: 569
A17: Total inventories | B17: =SUM(B14:B16) -> 3155 | C17: =SUM(C14:C16) -> 2639
A19: Other current assets | B19: 967 | C19: 1122
A20: Total current assets | B20: =B9+B10+B11+B17+B19 -> 12215 | C20: =C9+C10+C11+C17+C19 -> 10795
A22: Marketable securities — non-current | B22: 540 | C22: 825
A23: Investments | B23: 146 | C23: 103
A24: Property, plant and equipment | B24: 20253 | C24: 19440
A25: Less: Accumulated depreciation | B25: -12974 | C25: -12440
A26: Property, plant and equipment — net | B26: =B24+B25 -> 7279 | C26: =C24+C25 -> 7000
A27: Goodwill | B27: 6820 | C27: 5832
A28: Intangible assets — net | B28: 1820 | C28: 1342
A29: Prepaid pension benefits | B29: 74 | C29: 78
A30: Other assets | B30: 1262 | C30: 1275
A31: Total assets | B31: =B20+B22+B23+B26+B27+B28+B29+B30 -> 30156 | C31: =C20+C22+C23+C26+C27+C28+C29+C30 -> 27250
A33: Liabilities
A34: Current liabilities
A35: Short-term borrowings and current portion of long-term debt | B35: 1269 | C35: 613
A36: Accounts payable | B36: 1662 | C36: 1453
A37: Accrued payroll | B37: 778 | C37: 680
A38: Accrued income taxes | B38: 358 | C38: 252
A39: Other current liabilities | B39: 2022 | C39: 1899
A40: Total current liabilities | B40: =SUM(B35:B39) -> 6089 | C40: =SUM(C35:C39) -> 4897
A41: Long-term debt | B41: 4183 | C41: 5097
A42: Pension and postretirement benefits | B42: 2013 | C42: 2227
A43: Other liabilities | B43: 1854 | C43: 1727
A44: Total liabilities | B44: =SUM(B40:B43) -> 14139 | C44: =SUM(C40:C43) -> 13948
A46: Equity
...

Sheet Balance Vertical
A1: Consolidated Statement of Income
A2: 3M Company and Subsidiaries
A3: At December 31
E4: Análisis Vertical
B5: Year | C5: Year | E5: Year | F5: Year
A6: (Dollars in millions) | B6: 2010 | C6: 2009 | E6: 2010 | F6: 2009
A7: Assets
A8: Current assets
A9: Cash and cash equivalents | B9: 3377 | C9: 3040 | E9: =B9/$B$31 -> 0.11198435 | F9: =C9/$C$31 -> 0.11155963
A10: Marketable securities — current | B10: 1101 | C10: 744 | E10: =B10/$B$31 -> 0.036510147 | F10: =C10/$C$31 -> 0.027302752
A11: Accounts receivable | B11: 3615 | C11: 3250 | E11: =B11/$B$31 -> 0.11987664 | F11: =C11/$C$31 -> 0.11926606
A13: Inventories
A14: Finished goods | B14: 1476 | C14: 1255 | E14: =B14/$B$31 -> 0.048945483 | F14: =C14/$C$31 -> 0.046055046
A15: Work in process | B15: 950 | C15: 815 | E15: =B15/$B$31 -> 0.031502852 | F15: =C15/$C$31 -> 0.029908257
A16: Raw materials and supplies | B16: 729 | C16: 569 | E16: =B16/$B$31 -> 0.024174294 | F16: =C16/$C$31 -> 0.020880734
A17: Total inventories | B17: =SUM(B14:B16) -> 3155 | C17: =SUM(C14:C16) -> 2639 | E17: =SUM(E14:E16) -> 0.10462263 | F17: =C17/$C$31 -> 0.096844037
A19: Other current assets | B19: 967 | C19: 1122 | E19: =B19/$B$31 -> 0.032066587 | F19: =C19/$C$31 -> 0.041174312
A20: Total current assets | B20: =B9+B10+B11+B17+B19 -> 12215 | C20: =C9+C10+C11+C17+C19 -> 10795 | E20: =B20/$B$31 -> 0.40506035 | F20: =C20/$C$31 -> 0.39614679
A22: Marketable securities — non-current | B22: 540 | C22: 825 | E22: =B22/$B$31 -> 0.017906884 | F22: =C22/$C$31 -> 0.030275229
A23: Investments | B23: 146 | C23: 103 | E23: =B23/$B$31 -> 0.0048414909 | F23: =C23/$C$31 -> 0.0037798165
A24: Property, plant and equipment | B24: 20253 | C24: 19440 | E24: =B24/$B$31 -> 0.67160764 | F24: =C24/$C$31 -> 0.7133945
A25: Less: Accumulated depreciation | B25: -12974 | C25: -12440 | E25: =B25/$B$31 -> -0.43022947 | F25: =C25/$C$31 -> -0.45651376
A26: Property, plant and equipment — net | B26: =B24+B25 -> 7279 | C26: =C24+C25 -> 7000 | E26: =B26/$B$31 -> 0.24137817 | F26: =C26/$C$31 -> 0.25688073
A27: Goodwill | B27: 6820 | C27: 5832 | E27: =B27/$B$31 -> 0.22615732 | F27: =C27/$C$31 -> 0.21401835
A28: Intangible assets — net | B28: 1820 | C28: 1342 | E28: =B28/$B$31 -> 0.060352832 | F28: =C28/$C$31 -> 0.049247706
A29: Prepaid pension benefits | B29: 74 | C29: 78 | E29: =B29/$B$31 -> 0.0024539064 | F29: =C29/$C$31 -> 0.0028623853
A30: Other assets | B30: 1262 | C30: 1275 | E30: =B30/$B$31 -> 0.041849052 | F30: =C30/$C$31 -> 0.046788991
A31: Total assets | B31: =B20+B22+B23+B26+B27+B28+B29+B30 -> 30156 | C31: =C20+C22+C23+C26+C27+C28+C29+C30 -> 27250 | E31: =B31/B31 -> 1 | F31: =C31/$C$31 -> 1
A33: Liabilities
A34: Current liabilities
A35: Short-term borrowings and current portion of long-term debt | B35: 1269 | C35: 613 | E35: =B35/$B$56 -> 0.042081178 | F35: =C35/$C$56 -> 0.022495413
A36: Accounts payable | B36: 1662 | C36: 1453 | E36: =B36/$B$56 -> 0.05511341 | F36: =C36/$C$56 -> 0.053321101
A37: Accrued payroll | B37: 778 | C37: 680 | E37: =B37/$B$56 -> 0.025799178 | F37: =C37/$C$56 -> 0.024954128
A38: Accrued income taxes | B38: 358 | C38: 252 | E38: =B38/$B$56 -> 0.011871601 | F38: =C38/$C$56 -> 0.0092477064
A39: Other current liabilities | B39: 2022 | C39: 1899 | E39: =B39/$B$56 -> 0.067051333 | F39: =C39/$C$56 -> 0.069688073
A40: Total current liabilities | B40: =SUM(B35:B39) -> 6089 | C40: =SUM(C35:C39) -> 4897 | E40: =B40/$B$56 -> 0.2019167 | F40: =C40/$C$56 -> 0.17970642
A41: Long-term debt | B41: 4183 | C41: 5097 | E41: =B41/$B$56 -> 0.13871203 | F41: =C41/$C$56 -> 0.18704587
A42: Pension and postretirement benefits | B42: 2013 | C42: 2227 | E42: =B42/$B$56 -> 0.066752885 | F42: =C42/$C$56 -> 0.081724771
A43: Other liabilities | B43: 1854 | C43: 1727 | E43: =B43/$B$56 -> 0.061480302 | F43: =C43/$C$56 -> 0.063376147
A44: Total liabilities | B44: =SUM(B40:B43) -> 14139 | C44: =SUM(C40:C43) -> 13948 | E44: =B44/$B$56 -> 0.46886192 | F44: =C44/$C$56 -> 0.51185321
...

Sheet Balance Horizontal
A1: Consolidated Statement of Income
A2: 3M Company and Subsidiaries
A3: At December 31
E4: Análisis Horizontal
B5: Year | C5: Year | E5: Year | F5: Year
A6: (Dollars in millions) | B6: 2010 | C6: 2009 | E6: 2010 | F6: 2009
A7: Assets
A8: Current assets
A9: Cash and cash equivalents | B9: 3377 | C9: 3040 | E9: =B9/C9 -> 1.1108553 | F9: 1
A10: Marketable securities — current | B10: 1101 | C10: 744 | E10: =B10/C10 -> 1.4798387 | F10: 1
A11: Accounts receivable | B11: 3615 | C11: 3250 | E11: =B11/C11 -> 1.1123077 | F11: 1
A13: Inventories | F13: 1
A14: Finished goods | B14: 1476 | C14: 1255 | E14: =B14/C14 -> 1.1760956 | F14: 1
A15: Work in process | B15: 950 | C15: 815 | E15: =B15/C15 -> 1.1656442 | F15: 1
A16: Raw materials and supplies | B16: 729 | C16: 569 | E16: =B16/C16 -> 1.2811951 | F16: 1
A17: Total inventories | B17: =SUM(B14:B16) -> 3155 | C17: =SUM(C14:C16) -> 2639 | E17: =B17/C17 -> 1.1955286 | F17: 1
A19: Other current assets | B19: 967 | C19: 1122 | E19: =B19/C19 -> 0.86185383 | F19: 1
A20: Total current assets | B20: =B9+B10+B11+B17+B19 -> 12215 | C20: =C9+C10+C11+C17+C19 -> 10795 | E20: =B20/C20 -> 1.1315424 | F20: 1
A22: Marketable securities — non-current | B22: 540 | C22: 825 | E22: =B22/C22 -> 0.65454545 | F22: 1
A23: Investments | B23: 146 | C23: 103 | E23: =B23/C23 -> 1.4174757 | F23: 1
A24: Property, plant and equipment | B24: 20253 | C24: 19440 | E24: =B24/C24 -> 1.041821 | F24: 1
A25: Less: Accumulated depreciation | B25: -12974 | C25: -12440 | E25: =B25/C25 -> 1.042926 | F25: 1
A26: Property, plant and equipment — net | B26: =B24+B25 -> 7279 | C26: =C24+C25 -> 7000 | E26: =B26/C26 -> 1.0398571 | F26: 1
A27: Goodwill | B27: 6820 | C27: 5832 | E27: =B27/C27 -> 1.1694102 | F27: 1
A28: Intangible assets — net | B28: 1820 | C28: 1342 | E28: =B28/C28 -> 1.3561848 | F28: 1
A29: Prepaid pension benefits | B29: 74 | C29: 78 | E29: =B29/C29 -> 0.94871795 | F29: 1
A30: Other assets | B30: 1262 | C30: 1275 | E30: =B30/C30 -> 0.98980392 | F30: 1
A31: Total assets | B31: =B20+B22+B23+B26+B27+B28+B29+B30 -> 30156 | C31: =C20+C22+C23+C26+C27+C28+C29+C30 -> 27250 | E31: =B31/C31 -> 1.1066422 | F31: 1
A33: Liabilities
A34: Current liabilities
A35: Short-term borrowings and current portion of long-term debt | B35: 1269 | C35: 613 | E35: =B35/C35 -> 2.0701468 | F35: 1
A36: Accounts payable | B36: 1662 | C36: 1453 | E36: =B36/C36 -> 1.1438403 | F36: 1
A37: Accrued payroll | B37: 778 | C37: 680 | E37: =B37/C37 -> 1.1441176 | F37: 1
A38: Accrued income taxes | B38: 358 | C38: 252 | E38: =B38/C38 -> 1.4206349 | F38: 1
A39: Other current liabilities | B39: 2022 | C39: 1899 | E39: =B39/C39 -> 1.0647709 | F39: 1
A40: Total current liabilities | B40: =SUM(B35:B39) -> 6089 | C40: =SUM(C35:C39) -> 4897 | E40: =B40/C40 -> 1.2434143 | F40: 1
A41: Long-term debt | B41: 4183 | C41: 5097 | E41: =B41/C41 -> 0.82067883 | F41: 1
A42: Pension and postretirement benefits | B42: 2013 | C42: 2227 | E42: =B42/C42 -> 0.9039066 | F42: 1
A43: Other liabilities | B43: 1854 | C43: 1727 | E43: =B43/C43 -> 1.0735379 | F43: 1
A44: Total liabilities | B44: =SUM(B40:B43) -> 14139 | C44: =SUM(C40:C43) -> 13948 | E44: =B44/C44 -> 1.0136937 | F44: 1
...

Sheet Ratios
A1: Relaciones Financieras
A2: Medidas de Rendimiento Financiero
A3: Retorno sobre Activos (ROA)
A4: Rentabilidad | C4: 2010 | E4: 2009
A5: Utilidad Antes de Impuesto / Activo Total | B5: Retorno Sobre Activos | C5: =EE.RR!B26 -> 4085 | D5: =C5/C6 -> 0.13546226 | E5: =EE.RR!C26 -> 3193 | F5: =E5/E6 -> 0.11717431
C6: =Balance!B31 -> 30156 | E6: =Balance!C31 -> 27250
A8: Retorno sobre Patrimonio (ROE)
A9: Utilidad Antes de Impuesto / Patrimonio | B9: Retorno Sobre Patrimonio | C9: =C5 -> 4085 | D9: =C9/C10 -> 0.25504152 | E9: =E5 -> 3193 | F9: =E9/E10 -> 0.24003909
C10: =Balance!B54 -> 16017 | E10: =Balance!C54 -> 13302
A12: Eficiencia
A13: Utilidad Bruta / Ventas Netas | B13: Margen Bruto | C13: =EE.RR!B10 -> 12831 | D13: =C13/C14 -> 0.48124672 | E13: =EE.RR!C10 -> 11014 | F13: =E13/E14 -> 0.47632228
C14: =EE.RR!B7 -> 26662 | E14: =EE.RR!C7 -> 23123
A16: Utilidad Operacional / Ventas Netas | B16: Margen Operacional | C16: =EE.RR!B16 -> 5918 | D16: =C16/C17 -> 0.22196384 | E16: =EE.RR!C16 -> 4814 | F16: =E16/E17 -> 0.20819098
C17: =C14 -> 26662 | E17: =E14 -> 23123
A19: Utilidad Antes de Impuesto / Ventas Netas | B19: Margen Neto (1) | C19: =C9 -> 4085 | D19: =C19/C20 -> 0.15321431 | E19: =E9 -> 3193 | F19: =E19/E20 -> 0.13808762
C20: =C14 -> 26662 | E20: =E17 -> 23123
A22: Ventas Netas /Activo Total | B22: Rotación de Activos | C22: =C17 -> 26662 | D22: =C22/C23 -> 0.88413583 | E22: =E17 -> 23123 | F22: =E22/E23 -> 0.84855046
C23: =Balance!B31 -> 30156 | E23: =E6 -> 27250
A25: Ventas Netas / Inventarios (promedio o final) | B25: Rotación Inventarios (1) | C25: =C22 -> 26662 | D25: =C25/C26 -> 8.4507132 | E25: =E22 -> 23123 | F25: =E25/E26 -> 8.7620311
C26: =Balance!B17 -> 3155 | E26: =Balance!C17 -> 2639
A28: Costo de Ventas / Inventario (promedio o final) | B28: Rotación Inventarios (2) | C28: =EE.RR!B9 -> 13831 | D28: =C28/C29 -> 4.3838352 | E28: =EE.RR!C9 -> 12109 | F28: =E28/E29 -> 4.5884805
C29: =C26 -> 3155 | E29: =E26 -> 2639
A31: Ventas Netas / Cuentas por Cobrar (promedio o final) | B31: Rotación Cuentas por Cobrar | C31: =C25 -> 26662 | D31: =C31/C32 -> 7.3753804 | E31: =E25 -> 23123 | F31: =E31/E32 -> 7.1147692
C32: =Balance!B11 -> 3615 | E32: =Balance!C11 -> 3250
A34: Cuentas por Cobrar /Venta Diaria | B34: Periodo de Recuperación (dias) | C34: =C32 -> 3615 | D34: =C34/C35 -> 48.811042 | E34: =E32 -> 3250 | F34: =E34/E35 -> 50.598971
C35: =C31/360 -> 74.061111 | E35: =E31/360 -> 64.230556
A37: Ventas Netas / Activo Fijo Neto | B37: Rotación Activo Fijo (2) | C37: =C31 -> 26662 | D37: =C37/C38 -> 3.6628658 | E37: =E31 -> 23123 | F37: =E37/E38 -> 3.3032857
C38: =Balance!B26 -> 7279 | E38: =Balance!C26 -> 7000
A40: Inventarios / Costo de Venta dia | B40: Permanencia de Inventarios | C40: =C29 -> 3155 | D40: =C40/C41 -> 82.119876 | E40: =E29 -> 2639 | F40: =E40/E41 -> 78.457346
C41: =EE.RR!B9/360 -> 38.419444 | E41: =EE.RR!C9/360 -> 33.636111
A43: Endeudamiento
A45: Deuda Total /Patrimonio | B45: Deuda Total a Capital | C45: =Balance!B44 -> 14139 | D45: =C45/C46 -> 0.88274958 | E45: =Balance!C44 -> 13948 | F45: =E45/E46 -> 1.0485641
B46: Apalancamiento | C46: =Balance!B54 -> 16017 | E46: =Balance!C54 -> 13302
A48: Deuda Largo Plazo /Patrimonio | B48: Deuda Largo Plazo a Capital | C48: =Balance!B41+Balance!B42+Balance!B43 -> 8050 | D48: =C48/C49 -> 0.502591 | E48: =Balance!C41+Balance!C42+Balance!C43 -> 9051 | F48: =E48/E49 -> 0.680424
C49: =C46 -> 16017 | E49: =E46 -> 13302
A51: Deuda Total / Activo Total | B51: Deuda Total a Activo Total | C51: =C45 -> 14139 | D51: =C51/C52 -> 0.46886192 | E51: =E45 -> 13948 | F51: =E51/E52 -> 0.51185321
C52: =Balance!B31 -> 30156 | E52: =Balance!C31 -> 27250
A54: Activo Total / Patrimonio | B54: Leverage | C54: =C52 -> 30156 | D54: =C54/C55 -> 1.8827496 | E54: =E52 -> 27250 | F54: =E54/E55 -> 2.0485641
C55: =C46 -> 16017 | E55: =E46 -> 13302
A57: Liquidez
...

Sheet Du Pont
A1: Aplicación del Modelo Du Pont
A3: Retorno Sobre Patrimonio = Margen * Rotación * Endeudamiento
B5: Ut Neta | C5: = | D5: Ut Neta | E5: * | F5: Ventas | G5: * | H5: Activo Total
B6: Patrimonio | D6: Ventas | F6: Activo Total | H6: Patrimonio
A8: 3M
A9: 2010 | B9: =Ratios!D9 -> 0.25504152 | C9: = | D9: =EE.RR!B26/EE.RR!B7 -> 0.15321431 | F9: =EE.RR!B7/Balance!B31 -> 0.88413583 | H9: =Balance!B31/Balance!B54 -> 1.8827496
A11: 2009 | B11: =EE.RR!C26/Balance!C54 -> 0.24003909 | C11: = | D11: =EE.RR!C26/EE.RR!C7 -> 0.13808762 | F11: =EE.RR!C7/Balance!C31 -> 0.84855046 | H11: =Balance!C31/Balance!C54 -> 2.0485641
